<?xml version="1.0"?>
<robot xmlns:xacro="http://www.ros.org/wiki/xacro" >

<xacro:include filename="inertial_macros.xacro" />


    <material name="white">
        <color rgba="1 1 1 1" />
    </material>

    <material name="orange">
        <color rgba="1 0.3 0.1 1"/>
    </material>

    <material name="blue">
        <color rgba="0.2 0.2 1 1"/>
    </material>

    <material name="black">
        <color rgba="0 0 0 1"/>
    </material>

    <material name="red">
        <color rgba="1 0 0 1"/>
    </material>
    
    <!-- BASE LINK -->
    <link name="base_link">
    </link>
    <link name="base_footprint">
    </link>


    <joint name="base_footprint_joint" type="fixed">
        <parent link="base_link"/>
        <child link="base_footprint"/>
        <origin xyz="0 0 0" rpy="0 0 0"/>
    </joint>
    
   

    <!-- CHASSIS LINK -->

    <joint name="chassis_joint" type="fixed">
        <parent link="base_link"/>
        <child link="chassis"/>
        <origin xyz ="-0.055 0 0" />
    </joint>

    <link name="chassis">
        <visual>
            <origin xyz="0.14375 0 0.035"/>
            <geometry>
                <box size="0.2875 0.225 0.0325" />
            </geometry>
            <material name="white" />
        </visual>
        <collision>
            <origin xyz="0.14375 0 0.05"/>
            <geometry>
                <box size="0.2875 0.225 0.0325" />
            </geometry>
        </collision>
        <xacro:inertial_box mass="0.5" x="0.2875" y="0.225" z="0.0325">
            <origin xyz="0.14375 0 0.05" rpy="0 0 0"/>
        </xacro:inertial_box>
    </link>

    <joint name="left_wheel_joint" type="continuous">
        <parent link="base_link"/>
        <child link="left_wheel_back"/>
        <origin xyz="0 0.125 0" rpy="-${pi/2} 0 0" />
        <axis xyz="0 0 1"/>
    </joint>

    <link name="left_wheel_back">
    <visual>
      <geometry>
        <cylinder radius="0.05" length="0.03" />
      </geometry>
      <material name="black" />
    </visual>
    <collision>
      <geometry>
        <cylinder radius="0.05" length="0.03" />
      </geometry>
    </collision>
    <xacro:inertial_cylinder mass="0.1" length="0.03" radius="0.05">
            <origin xyz="0 0 0" rpy="0 0 0"/>
        </xacro:inertial_cylinder>
    </link>
    

    <joint name="right_wheel_joint" type="continuous">
        <parent link="base_link"/>
        <child link="right_wheel_back"/>
        <origin xyz="0 -0.125 0" rpy="${pi/2} 0 0" />
        <axis xyz="0 0 -1"/>
    </joint>

    <link name="right_wheel_back">
    <visual>
      <geometry>
        <cylinder radius="0.05" length="0.03" />
      </geometry>
      <material name="black" />
    </visual>
    <collision>
      <geometry>
        <cylinder radius="0.05" length="0.03" />
      </geometry>
    </collision>
    <xacro:inertial_cylinder mass="0.1" length="0.03" radius="0.05">
            <origin xyz="0 0 0" rpy="0 0 0"/>
        </xacro:inertial_cylinder>
    </link>

    <joint name="left_wheel_joint_front" type="fixed">
        <parent link="base_link"/>
        <child link="left_wheel_front"/>
        <origin xyz="0.1825 0.125 0" rpy="-${pi/2} 0 0" />
        <axis xyz="0 0 1"/>
    </joint>

    <link name="left_wheel_front">
    <visual>
      <geometry>
        <cylinder radius="0.05" length="0.03" />
      </geometry>
      <material name="black" />
    </visual>
    <collision>
      <geometry>
        <cylinder radius="0.05" length="0.03" />
      </geometry>
      <material name="black" />
    </collision>
    <xacro:inertial_cylinder mass="0.1" length="0.03" radius="0.05">
            <origin xyz="0 0 0" rpy="0 0 0"/>
        </xacro:inertial_cylinder>
    </link>

    <joint name="right_wheel_joint_front" type="fixed">
        <parent link="base_link"/>
        <child link="right_wheel_front"/>
        <origin xyz="0.1825 -0.125 0" rpy="${pi/2} 0 0" />
        <axis xyz="0 0 -1"/>
    </joint>

    <link name="right_wheel_front">
    <visual>
      <geometry>
        <cylinder radius="0.05" length="0.03" />
      </geometry>
      <material name="black" />
    </visual>
    <collision>
      <geometry>
        <cylinder radius="0.05" length="0.03" />
      </geometry>
      <material name="black" />
    </collision>
    <xacro:inertial_cylinder mass="0.1" length="0.03" radius="0.05">
            <origin xyz="0 0 0" rpy="0 0 0"/>
        </xacro:inertial_cylinder>
    </link>
  

</robot>
